<?xml version="1.0" encoding="UTF-8"?>
<!-- Generated by org.testng.reporters.JUnitReportReporter -->
<testsuite skipped="0" hostname="DESKTOP-DLGL6VP" name="SeleniumPractice.ExceptionTImeout" tests="1" failures="0" timestamp="25 May 2020 18:50:04 GMT" time="2.023" errors="1">
  <testcase name="intLoop" time="2.023" classname="SeleniumPractice.ExceptionTImeout">
    <error type="org.testng.TestException" message="
Expected exception of type class java.lang.NumberFormatException but got org.testng.internal.thread.ThreadTimeoutException: Method SeleniumPractice.ExceptionTImeout.intLoop() didn&#039;t finish within the time-out 2000">
      <![CDATA[org.testng.TestException: 
Expected exception of type class java.lang.NumberFormatException but got org.testng.internal.thread.ThreadTimeoutException: Method SeleniumPractice.ExceptionTImeout.intLoop() didn't finish within the time-out 2000
at org.testng.internal.ExpectedExceptionsHolder.wrongException(ExpectedExceptionsHolder.java:68)
at org.testng.internal.Invoker.considerExceptions(Invoker.java:1130)
at org.testng.internal.Invoker.invokeMethod(Invoker.java:615)
at org.testng.internal.Invoker.invokeTestMethod(Invoker.java:719)
at org.testng.internal.Invoker.invokeTestMethods(Invoker.java:989)
at org.testng.internal.TestMethodWorker.invokeTestMethods(TestMethodWorker.java:125)
at org.testng.internal.TestMethodWorker.run(TestMethodWorker.java:109)
at org.testng.TestRunner.privateRun(TestRunner.java:648)
at org.testng.TestRunner.run(TestRunner.java:505)
at org.testng.SuiteRunner.runTest(SuiteRunner.java:455)
at org.testng.SuiteRunner.runSequentially(SuiteRunner.java:450)
at org.testng.SuiteRunner.privateRun(SuiteRunner.java:415)
at org.testng.SuiteRunner.run(SuiteRunner.java:364)
at org.testng.SuiteRunnerWorker.runSuite(SuiteRunnerWorker.java:52)
at org.testng.SuiteRunnerWorker.run(SuiteRunnerWorker.java:84)
at org.testng.TestNG.runSuitesSequentially(TestNG.java:1208)
at org.testng.TestNG.runSuitesLocally(TestNG.java:1137)
at org.testng.TestNG.runSuites(TestNG.java:1049)
at org.testng.TestNG.run(TestNG.java:1017)
at org.testng.remote.AbstractRemoteTestNG.run(AbstractRemoteTestNG.java:115)
at org.testng.remote.RemoteTestNG.initAndRun(RemoteTestNG.java:251)
at org.testng.remote.RemoteTestNG.main(RemoteTestNG.java:77)
Caused by: org.testng.internal.thread.ThreadTimeoutException: Method SeleniumPractice.ExceptionTImeout.intLoop() didn't finish within the time-out 2000
at java.io.FileOutputStream.writeBytes(Native Method)
at java.io.FileOutputStream.write(Unknown Source)
at java.io.BufferedOutputStream.flushBuffer(Unknown Source)
at java.io.BufferedOutputStream.flush(Unknown Source)
at java.io.PrintStream.write(Unknown Source)
at sun.nio.cs.StreamEncoder.writeBytes(Unknown Source)
at sun.nio.cs.StreamEncoder.implFlushBuffer(Unknown Source)
at sun.nio.cs.StreamEncoder.flushBuffer(Unknown Source)
at java.io.OutputStreamWriter.flushBuffer(Unknown Source)
at java.io.PrintStream.write(Unknown Source)
at java.io.PrintStream.print(Unknown Source)
at java.io.PrintStream.println(Unknown Source)
at SeleniumPractice.ExceptionTImeout.intLoop(ExceptionTImeout.java:12)
at sun.reflect.NativeMethodAccessorImpl.invoke0(Native Method)
at sun.reflect.NativeMethodAccessorImpl.invoke(Unknown Source)
at sun.reflect.DelegatingMethodAccessorImpl.invoke(Unknown Source)
at java.lang.reflect.Method.invoke(Unknown Source)
at org.testng.internal.MethodInvocationHelper.invokeMethod(MethodInvocationHelper.java:124)
at org.testng.internal.InvokeMethodRunnable.runOne(InvokeMethodRunnable.java:54)
at org.testng.internal.InvokeMethodRunnable.run(InvokeMethodRunnable.java:40)
at java.util.concurrent.Executors$RunnableAdapter.call(Unknown Source)
at java.util.concurrent.FutureTask.run(Unknown Source)
at java.util.concurrent.ThreadPoolExecutor.runWorker(Unknown Source)
at java.util.concurrent.ThreadPoolExecutor$Worker.run(Unknown Source)
at java.lang.Thread.run(Unknown Source)
]]>
    </error>
  </testcase> <!-- intLoop -->
</testsuite> <!-- SeleniumPractice.ExceptionTImeout -->
